<robot
  name="robot">
  <link
    name="base_link">
    <visual>
      <origin
        xyz="0 0 0"
        rpy="0 0 0" />
      <geometry>
        <mesh
          filename="package://robot/meshes/base_link.STL" />
      </geometry>
      <material
        name="">
        <color
          rgba="1 1 1 1" />
      </material>
    </visual>
    <collision>
      <origin
        xyz="0 0 0"
        rpy="0 0 0" />
      <geometry>
        <mesh
          filename="package://robot/meshes/base_link.STL" />
      </geometry>
    </collision>

    <inertial>
        <origin xyz="0 0 0" rpy="0 0 0" />
        <mass value="1" />
        <inertia
          ixx="1.0" ixy="0.0" ixz="0.0"
          iyy="1.0" iyz="0.0"
          izz="1.0" />
    </inertial>
  </link>
  <link
    name="left_leg">
    <visual>
      <origin
        xyz="0 0 0"
        rpy="0 0 0" />
      <geometry>
        <mesh
          filename="package://robot/meshes/left_leg.STL" />
      </geometry>
      <material
        name="">
        <color
          rgba="1 1 1 1" />
      </material>
    </visual>
    <collision>
      <origin
        xyz="0 0 0"
        rpy="0 0 0" />
      <geometry>
        <mesh
          filename="package://robot/meshes/left_leg.STL" />
      </geometry>
    </collision>
    <inertial>
        <origin xyz="0 0 0" rpy="0 0 0" />
        <mass value="1" />
        <inertia
          ixx="1.0" ixy="0.0" ixz="0.0"
          iyy="1.0" iyz="0.0"
          izz="1.0" />
    </inertial>
  </link>
  <joint
    name="left_leg_joint"
    type="fixed">
    <origin
      xyz="0 2.2 2.5"
      rpy="0 0 0" />
    <parent
      link="base_link" />
    <child
      link="left_leg" />
    <axis
      xyz="0 0 0" />
  </joint>
  <link
    name="left_base">
    <visual>
      <origin
        xyz="0 0 0"
        rpy="0 0 0" />
      <geometry>
        <mesh
          filename="package://robot/meshes/left_base.STL" />
      </geometry>
      <material
        name="">
        <color
          rgba="1 1 1 1" />
      </material>
    </visual>
    <collision>
      <origin
        xyz="0 0 0"
        rpy="0 0 0" />
      <geometry>
        <mesh
          filename="package://robot/meshes/left_base.STL" />
      </geometry>
    </collision>
    <inertial>
        <origin xyz="0 0 0" rpy="0 0 0" />
        <mass value="1" />
        <inertia
          ixx="1.0" ixy="0.0" ixz="0.0"
          iyy="1.0" iyz="0.0"
          izz="1.0" />
    </inertial>
  </link>
  <joint
    name="left_base_joint"
    type="fixed">
    <origin
      xyz="0 0 -6"
      rpy="4.8762E-29 3.4915E-15 1.3966E-14" />
    <parent
      link="left_leg" />
    <child
      link="left_base" />
    <axis
      xyz="0 0 0" />
  </joint>
  <link
    name="left_front_wheel">
    <visual>
      <origin
        xyz="0 0 0"
        rpy="0 0 0" />
      <geometry>
        <mesh
          filename="package://robot/meshes/left_front_wheel.STL" />
      </geometry>
      <material
        name="">
        <color
          rgba="1 1 1 1" />
      </material>
    </visual>
    <collision>
      <origin
        xyz="0 0 0"
        rpy="0 0 0" />
      <geometry>
        <mesh
          filename="package://robot/meshes/left_front_wheel.STL" />
      </geometry>
    </collision>
    <inertial>
        <origin xyz="0 0 0" rpy="0 0 0" />
        <mass value="1" />
        <inertia
          ixx="1.0" ixy="0.0" ixz="0.0"
          iyy="1.0" iyz="0.0"
          izz="1.0" />
    </inertial>
  </link>
  <joint
    name="left_front_wheel_joint"
    type="continuous">
    <origin
      xyz="1.3333 0 -0.85"
      rpy="0 -3.4915E-15 -1.3966E-14" />
    <parent
      link="left_base" />
    <child
      link="left_front_wheel" />
    <axis
      xyz="0 1 0" />
  </joint>
  <link
    name="left_back_wheel">
    <visual>
      <origin
        xyz="0 0 0"
        rpy="0 0 0" />
      <geometry>
        <mesh
          filename="package://robot/meshes/left_back_wheel.STL" />
      </geometry>
      <material
        name="">
        <color
          rgba="1 1 1 1" />
      </material>
    </visual>
    <collision>
      <origin
        xyz="0 0 0"
        rpy="0 0 0" />
      <geometry>
        <mesh
          filename="package://robot/meshes/left_back_wheel.STL" />
      </geometry>
    </collision>
    <inertial>
        <origin xyz="0 0 0" rpy="0 0 0" />
        <mass value="1" />
        <inertia
          ixx="1.0" ixy="0.0" ixz="0.0"
          iyy="1.0" iyz="0.0"
          izz="1.0" />
    </inertial>
  </link>
  <joint
    name="left_back_wheel_joint"
    type="continuous">
    <origin
      xyz="-1.3333 0 -0.85"
      rpy="0 0 -1.7025E-43" />
    <parent
      link="left_base" />
    <child
      link="left_back_wheel" />
    <axis
      xyz="0 1 0" />
  </joint>
  <link
    name="right_leg">
    <visual>
      <origin
        xyz="0 0 0"
        rpy="0 0 0" />
      <geometry>
        <mesh
          filename="package://robot/meshes/right_leg.STL" />
      </geometry>
      <material
        name="">
        <color
          rgba="1 1 1 1" />
      </material>
    </visual>
    <collision>
      <origin
        xyz="0 0 0"
        rpy="0 0 0" />
      <geometry>
        <mesh
          filename="package://robot/meshes/right_leg.STL" />
      </geometry>
    </collision>
    <inertial>
        <origin xyz="0 0 0" rpy="0 0 0" />
        <mass value="1" />
        <inertia
          ixx="1.0" ixy="0.0" ixz="0.0"
          iyy="1.0" iyz="0.0"
          izz="1.0" />
    </inertial>
  </link>
  <joint
    name="right_leg_joint"
    type="fixed">
    <origin
      xyz="0 -2.2 2.5"
      rpy="0 0 0" />
    <parent
      link="base_link" />
    <child
      link="right_leg" />
    <axis
      xyz="0 0 0" />
  </joint>
  <link
    name="right_base">
    <visual>
      <origin
        xyz="0 0 0"
        rpy="0 0 0" />
      <geometry>
        <mesh
          filename="package://robot/meshes/right_base.STL" />
      </geometry>
      <material
        name="">
        <color
          rgba="1 1 1 1" />
      </material>
    </visual>
    <collision>
      <origin
        xyz="0 0 0"
        rpy="0 0 0" />
      <geometry>
        <mesh
          filename="package://robot/meshes/right_base.STL" />
      </geometry>
    </collision>
    <inertial>
        <origin xyz="0 0 0" rpy="0 0 0" />
        <mass value="1" />
        <inertia
          ixx="1.0" ixy="0.0" ixz="0.0"
          iyy="1.0" iyz="0.0"
          izz="1.0" />
    </inertial>
  </link>
  <joint
    name="right_base_joint"
    type="fixed">
    <origin
      xyz="0 0 -6"
      rpy="0 3.4915E-15 0" />
    <parent
      link="right_leg" />
    <child
      link="right_base" />
    <axis
      xyz="0 0 0" />
  </joint>
  <link
    name="right_front_wheel">
    <visual>
      <origin
        xyz="0 0 0"
        rpy="0 0 0" />
      <geometry>
        <mesh
          filename="package://robot/meshes/right_front_wheel.STL" />
      </geometry>
      <material
        name="">
        <color
          rgba="1 1 1 1" />
      </material>
    </visual>
    <collision>
      <origin
        xyz="0 0 0"
        rpy="0 0 0" />
      <geometry>
        <mesh
          filename="package://robot/meshes/right_front_wheel.STL" />
      </geometry>
    </collision>
    <inertial>
        <origin xyz="0 0 0" rpy="0 0 0" />
        <mass value="1" />
        <inertia
          ixx="1.0" ixy="0.0" ixz="0.0"
          iyy="1.0" iyz="0.0"
          izz="1.0" />
    </inertial>
  </link>
  <joint
    name="right_front_wheel_joint"
    type="continuous">
    <origin
      xyz="1.3333 0 -0.85"
      rpy="0 0 0" />
    <parent
      link="right_base" />
    <child
      link="right_front_wheel" />
    <axis
      xyz="0 1 0" />
  </joint>
  <link
    name="right_back_wheel">
    <visual>
      <origin
        xyz="0 0 0"
        rpy="0 0 0" />
      <geometry>
        <mesh
          filename="package://robot/meshes/right_back_wheel.STL" />
      </geometry>
      <material
        name="">
        <color
          rgba="1 1 1 1" />
      </material>
    </visual>
    <collision>
      <origin
        xyz="0 0 0"
        rpy="0 0 0" />
      <geometry>
        <mesh
          filename="package://robot/meshes/right_back_wheel.STL" />
      </geometry>
    </collision>
    <inertial>
        <origin xyz="0 0 0" rpy="0 0 0" />
        <mass value="1" />
        <inertia
          ixx="1.0" ixy="0.0" ixz="0.0"
          iyy="1.0" iyz="0.0"
          izz="1.0" />
    </inertial>
  </link>
  <joint
    name="right_back_wheel_joint"
    type="continuous">
    <origin
      xyz="-1.3333 0 -0.85"
      rpy="0 0 0" />
    <parent
      link="right_base" />
    <child
      link="right_back_wheel" />
    <axis
      xyz="0 1 0" />
  </joint>
  <link
    name="gripper_pole">
    <visual>
      <origin
        xyz="0 0 0"
        rpy="0 0 0" />
      <geometry>
        <mesh
          filename="package://robot/meshes/gripper_pole.STL" />
      </geometry>
      <material
        name="">
        <color
          rgba="1 1 1 1" />
      </material>
    </visual>
    <collision>
      <origin
        xyz="0 0 0"
        rpy="0 0 0" />
      <geometry>
        <mesh
          filename="package://robot/meshes/gripper_pole.STL" />
      </geometry>
    </collision>
    <inertial>
        <origin xyz="0 0 0" rpy="0 0 0" />
        <mass value="1" />
        <inertia
          ixx="1.0" ixy="0.0" ixz="0.0"
          iyy="1.0" iyz="0.0"
          izz="1.0" />
    </inertial>
  </link>
  <joint
    name="gripper_pole_axis"
    type="prismatic">
    <origin
      xyz="2.9 0 2"
      rpy="0 0 0" />
    <parent
      link="base_link" />
    <child
      link="gripper_pole" />
    <axis
      xyz="-1 0 0" />
    <limit
      lower="-2"
      upper="0"
      effort="1000"
      velocity="0.5" />
  </joint>
  <link
    name="head">
    <visual>
      <origin
        xyz="0 0 0"
        rpy="0 0 0" />
      <geometry>
        <mesh
          filename="package://robot/meshes/head.STL" />
      </geometry>
      <material
        name="">
        <color
          rgba="1 1 1 1" />
      </material>
    </visual>
    <collision>
      <origin
        xyz="0 0 0"
        rpy="0 0 0" />
      <geometry>
        <mesh
          filename="package://robot/meshes/head.STL" />
      </geometry>
    </collision>
    <inertial>
        <origin xyz="0 0 0" rpy="0 0 0" />
        <mass value="1" />
        <inertia
          ixx="1.0" ixy="0.0" ixz="0.0"
          iyy="1.0" iyz="0.0"
          izz="1.0" />
    </inertial>
  </link>
  <joint
    name="head_joint"
    type="continuous">
    <origin
      xyz="0 0 3"
      rpy="0 0 0" />
    <parent
      link="base_link" />
    <child
      link="head" />
    <axis
      xyz="0 0 1" />
  </joint>
  <link
    name="box">
    <visual>
      <origin
        xyz="0 0 0"
        rpy="0 0 0" />
      <geometry>
        <mesh
          filename="package://robot/meshes/box.STL" />
      </geometry>
      <material
        name="">
        <color
          rgba="1 1 1 1" />
      </material>
    </visual>
    <collision>
      <origin
        xyz="0 0 0"
        rpy="0 0 0" />
      <geometry>
        <mesh
          filename="package://robot/meshes/box.STL" />
      </geometry>
    </collision>
    <inertial>
        <origin xyz="0 0 0" rpy="0 0 0" />
        <mass value="1" />
        <inertia
          ixx="1.0" ixy="0.0" ixz="0.0"
          iyy="1.0" iyz="0.0"
          izz="1.0" />
    </inertial>
  </link>
  <joint
    name="box_joint"
    type="fixed">
    <origin
      xyz="1.814 0 1.414"
      rpy="0 0 0" />
    <parent
      link="head" />
    <child
      link="box" />
    <axis
      xyz="0 0 0" />
  </joint>

  <transmission name="$trans1">
      <type>transmission_interface/SimpleTransmission</type>
      <actuator name="$motor1">
        <mechanicalReduction>1</mechanicalReduction>
      </actuator>
      <joint name="left_front_wheel_joint">
        <hardwareInterface>VelocityJointInterface</hardwareInterface>
      </joint>
    </transmission>

  <transmission name="$trans2">
      <type>transmission_interface/SimpleTransmission</type>
      <actuator name="$motor2">
        <mechanicalReduction>1</mechanicalReduction>
      </actuator>
      <joint name="left_back_wheel_joint">
        <hardwareInterface>VelocityJointInterface</hardwareInterface>
      </joint>
    </transmission>

  <transmission name="$trans3">
      <type>transmission_interface/SimpleTransmission</type>
      <actuator name="$motor3">
        <mechanicalReduction>1</mechanicalReduction>
      </actuator>
      <joint name="right_front_wheel_joint">
        <hardwareInterface>VelocityJointInterface</hardwareInterface>
      </joint>
    </transmission>

  <transmission name="$trans4">
      <type>transmission_interface/SimpleTransmission</type>
      <actuator name="$motor4">
        <mechanicalReduction>1</mechanicalReduction>
      </actuator>
      <joint name="right_back_wheel_joint">
        <hardwareInterface>VelocityJointInterface</hardwareInterface>
      </joint>
    </transmission>

  <!-- Gazebo plugin for ROS Control -->
  <gazebo>
    <plugin name="gazebo_ros_control" filename="libgazebo_ros_control.so">
    </plugin>
    <plugin name="joint_state_publisher" filename="libgazebo_ros_joint_state_publisher.so">
      <jointName>
          left_front_wheel_joint, left_back_wheel_joint, right_front_wheel_joint, right_back_wheel_joint
      </jointName>
      <updateRate>50</updateRate>
      <alwaysOn>true</alwaysOn>
    </plugin>
  </gazebo>

</robot>
